Workbook

Sheet Valuation
D1: 1 | E1: 2 | F1: 3 | G1: 4 | H1: 5
A2: Particulars | D2: Forecast
B3: Unit | D3: 2025 | E3: =D3+1 -> 2026 | F3: =E3+1 -> 2027 | G3: =F3+1 -> 2028 | H3: =G3+1 -> 2029
A4: EBIT | D4: ='P&L'!H21 -> 15298.756 | E4: ='P&L'!I21 -> 17028.366 | F4: ='P&L'!J21 -> 18844.468 | G4: ='P&L'!K21 -> 20720.042 | H4: ='P&L'!L21 -> 22622.632
A5: Tax Rate | D5: ='P&L'!H52 -> 0.18930474 | E5: ='P&L'!I52 -> 0.18930474 | F5: ='P&L'!J52 -> 0.18930474 | G5: ='P&L'!K52 -> 0.18930474 | H5: ='P&L'!L52 -> 0.18930474
A6: Less: Income taxes | D6: =D4*D5 -> 2896.127 | E6: =E4*E5 -> 3223.5504 | F6: =F4*F5 -> 3567.3471 | G6: =G4*G5 -> 3922.4021 | H6: =H4*H5 -> 4282.5714
A7: NOPAT | D7: =D4-D6 -> 12402.629 | E7: =E4-E6 -> 13804.816 | F7: =F4-F6 -> 15277.121 | G7: =G4-G6 -> 16797.64 | H7: =H4-H6 -> 18340.06
A8: Add: D&A | D8: ='P&L'!H57 -> 1122.3584 | E8: ='P&L'!I57 -> 1187.1028 | F8: ='P&L'!J57 -> 1246.7465 | G8: ='P&L'!K57 -> 1316.6385 | H8: ='P&L'!L57 -> 1327.9671
A9: Changes in WC | D9: =SUM(CFS!C15:C19) -> 1896.5408 | E9: =SUM(CFS!D15:D19) -> 1646.8393 | F9: =SUM(CFS!E15:E19) -> 1852.4703 | G9: =SUM(CFS!F15:F19) -> 1829.8035 | H9: =SUM(CFS!G15:G19) -> 1774.6546
A10: Less: Capex | D10: =CFS!C23 -> -1404 | E10: =CFS!D23 -> -1282.8424 | F10: =CFS!E23 -> -1430.0678 | G10: =CFS!F23 -> -1428.0583 | H10: =CFS!G23 -> -1393.1438
A11: FCFF | D11: =SUM(D7:D10) -> 14017.528 | E11: =SUM(E7:E10) -> 15355.915 | F11: =SUM(F7:F10) -> 16946.27 | G11: =SUM(G7:G10) -> 18516.023 | H11: =SUM(H7:H10) -> 20049.538
E12: =E11/D11-1 -> 0.095479532 | F12: =F11/E11-1 -> 0.10356625 | G12: =G11/F11-1 -> 0.092631203 | H12: =H11/G11-1 -> 0.082820965
A13: Terminal value | H13: =H11*(1+B19)/(B18-B19) -> 449093.39
A14: Total Cash Flow | D14: =D11+D13 -> 14017.528 | E14: =E11+E13 -> 15355.915 | F14: =F11+F13 -> 16946.27 | G14: =G11+G13 -> 18516.023 | H14: =H11+H13 -> 469142.93
A15: PV of cashflows | D15: =D14/(1+$B$18)^D1 -> 13220.165 | E15: =E14/(1+$B$18)^E1 -> 13658.613 | F15: =F14/(1+$B$18)^F1 -> 14215.772 | G15: =G14/(1+$B$18)^G1 -> 14649.051 | H15: =H14/(1+$B$18)^H1 -> 350051.88
A17: Terminal Value Method | F17: WACC
A18: WACC | B18: =('Cost of equity'!B16*'Cost of equity'!C22/'Cost of equity'!E22)+('Cost of debt'!B17*'Cost of equity'!D22/'Cost of equity'!E22) -> 0.060314141 | D18: GROWTH | E18: =B26 -> 91.483907 | F18: =G18-0.5% -> 0.0453 | G18: =H18-0.5% -> 0.0503 | H18: =I18-0.5% -> 0.0553 | I18: 0.0603 | J18: =I18+0.5% -> 0.0653 | K18: =J18+0.5% -> 0.0703 | L18: =K18+0.5% -> 0.0753
A19: Long term growth rate | B19: 0.015 | E19: 0.011 | F19: 124.26637 | G19: 107.81467 | H19: 95.082147 | I19: 84.937075 | J19: 76.664587 | K19: 69.790917 | L19: 63.989662
A20: Value of firm | B20: =SUM(D15:H15) -> 405795.48 | E20: 0.013 | F20: 131.284 | G20: 113.01818 | H20: 99.076098 | I20: 88.086473 | J20: 79.202411 | K20: 71.872622 | L20: 65.722799
A21: Less: Value of debt | B21: =SUM('Balance Sheet'!G30:G31,'Balance Sheet'!G34) -> 44522 | E21: 0.015 | F21: 139.22804 | G21: 118.81131 | H21: 103.46647 | I21: 91.513963 | J21: 81.942049 | K21: 74.104903 | L21: 67.570904
A22: Add:Cash and cash equivalents | B22: ='Balance Sheet'!G6+'Balance Sheet'!G7 -> 12848 | E22: 0.017 | F22: 148.29492 | G22: 125.30032 | H22: 108.31537 | I22: 95.258081 | J22: 84.908573 | K22: 76.504709 | L22: 69.545809
A23: Add: Investments | B23: =SUM('Balance Sheet'!F10,'Balance Sheet'!F16:F17) -> 21089 | E23: 0.019 | F23: 158.74079 | G23: 132.61859 | H23: 113.69858 | I23: 99.364825 | J23: 88.131383 | K23: 79.091634 | L23: 71.661027
A24: Value of equity | B24: =B20-B21+B22+B23 -> 395210.48 | E24: 0.021 | F24: 170.90614 | G24: 140.93594 | H24: 119.70957 | I24: 103.88956 | J24: 91.645193 | K24: 81.888453 | L24: 73.932062
A25: No of shares outstanding | B25: ='P&L'!G43 -> 4320 | E25: 0.023 | F25: 185.25363 | G25: 150.47196 | H25: 126.46496 | I25: 108.89952 | J25: 95.491277 | K25: 84.921788 | L25: 76.37679
A26: Fair Value / share | B26: =B24/B25 -> 91.483907 | E26: 0.025 | F26: 202.4282 | G26: 161.51564 | H26: 134.11215 | I26: 114.47718 | J26: 99.719107 | K26: 88.222968 | L26: 79.015929
E27: 0.027 | F27: 223.35677 | G27: 174.45524 | H27: 142.84021 | I27: 120.72483 | J27: 104.38849 | K27: 91.829107 | L27: 81.873631
A31: EV/EBIDTA Exit Multiple Method | D31: Peers Forward EV/EBIDTA(2Yr)
A32: ∑ PV of FCFF | B32: =SUM(E37:I37) -> 70703.603 | D32: Dr Pepper | E32: Pepsi | F32: Monster
A33: EV/EBIDTA Exit Multiple | B33: =AVERAGE(D33:F33) -> 14.966667 | D33: 11.6 | E33: 11.1 | F33: 22.2
A34: EBIDTA (2029F) (USD Million) | B34: ='P&L'!L56 -> 23950.599
A35: Terminal Value | B35: =B34*B33 -> 358460.63
A36: PV Terminal Value | B36: =B35*I36 -> 267466.07 | D36: Discount Factor (PVIF) | E36: =1/(1+$B$18)^D1 -> 0.94311673 | F36: =1/(1+$B$18)^E1 -> 0.88946916 | G36: =1/(1+$B$18)^F1 -> 0.83887324 | H36: =1/(1+$B$18)^G1 -> 0.79115538 | I36: =1/(1+$B$18)^H1 -> 0.74615187
A37: Value of Firm (Enterprise Value) | B37: =B36+B32 -> 338169.67 | D37: Present Value of FCFF | E37: =D11*E36 -> 13220.165 | F37: =E11*F36 -> 13658.613 | G37: =F11*G36 -> 14215.772 | H37: =G11*H36 -> 14649.051 | I37: =H11*I36 -> 14960
A38: Value of Debt | B38: =B21 -> 44522
A39: Value of Cash and STI | B39: =B22 -> 12848
A40: Add: Investments | B40: =SUM('Balance Sheet'!F26,'Balance Sheet'!F32:F33) -> 25140
A41: Value of equity | B41: =B37-B38+B39+B40 -> 331635.67
A42: No of shares outstanding | B42: =B25 -> 4320
A43: Fair Value / share | B43: =B41/B42 -> 76.767517
A44: Discount/Premium to CMP ($69.56) | B44: =(B43/'Cost of equity'!E284)-1 -> 0.10361582

Sheet Cost of equity
A2: Particulars | B2: Unit
A5: Cost of equity
A6: Risk free rate of returns | B6: 0.04506
A7: Returns from Market (Historical) | B7: =B13 -> 0.075209579
A9: Date | B9: Year | C9: Index value
A10: 31048 | B10: 1985 | C10: 1097.02
A11: 45708 | B11: 2025 | C11: 20149.85
A12: Total Time | B12: =YEARFRAC(A10,A11,1) -> 40.137563
A13: CAGR | B13: =(C11/C10)^(1/B12)-1 -> 0.075209579
A14: Marginal tax rate | B14: 0.27
A15: Bottom-up beta | B15: =F31 -> 0.5663343
A16: Cost of equity (CAPM) | B16: =B6+(B7-B6)*B15 -> 0.062134741
A21: Name | B21: Regression Beta | C21: Average Market Cap | D21: Average Debt | E21: Total Capital | F21: Unlevered beta
A22: CocaCola | B22: =E35 -> 0.58776063 | C22: =AVERAGE(275082,254779,268203) -> 266021.33 | D22: =AVERAGE(27518,28401,29951) -> 28623.333 | E22: =D22+C22 -> 294644.67 | F22: =(B22/(D22*(1-$B$14)+C22))*C22 -> 0.54495624
A24: Name | B24: Regression Beta | C24: Average Market Cap | D24: Average Debt | E24: Total Capital | F24: Unlevered beta
A25: Peers
A26: Keurig Dr. pepper | B26: =H35 -> 0.53479868 | C26: =AVERAGE(50565,46593,43569) -> 46909 | D26: =AVERAGE(11432,12924,15044) -> 13133.333 | E26: =D26+C26 -> 60042.333 | F26: =(B26/(D26*(1-$B$14)+C26))*C26 -> 0.44404424
A27: Pepsi Co. | B27: =K35 -> 0.48002386 | C27: =AVERAGE(251832,236278,212201) -> 233437 | D27: =AVERAGE(33723,34102,35040) -> 34288.333 | E27: =D27+C27 -> 267725.33 | F27: =(B27/(D27*(1-$B$14)+C27))*C27 -> 0.43353743
A28: Monster beverages | B28: =N35 -> 0.69768926 | C28: =AVERAGE(53011,59940,51116) -> 54689 | D28: 0 | E28: =D28+C28 -> 54689 | F28: =(B28/(D28*(1-$B$14)+C28))*C28 -> 0.69768926
E29: Average Unlevered beta | F29: =AVERAGE(F26:F28) -> 0.52509031
A30: Relevered beta | B30: Regression Beta | C30: Average Market Cap | D30: Average Debt | E30: Total Capital | F30: Re levered beta
A31: Average Unlevered beta | B31: =F29 -> 0.52509031 | C31: =C22 -> 266021.33 | D31: =D22 -> 28623.333 | E31: =E22 -> 294644.67 | F31: =(B31/C31)*(D31*(1-B14)+C31) -> 0.5663343
B34: NYSE | E34: CocaCola | H34: Keurig Dr. pepper | K34: Pepsi Co. | N34: Monster beverages
A35: Regression Beta | B35: =_xlfn.COVARIANCE.S($C$39:$C$232,C39:C232)/_xlfn.VAR.S($C$39:$C$232,C39:C232) -> 1.0026042 | E35: =_xlfn.COVARIANCE.S($C$39:$C$284,F39:F284)/_xlfn.VAR.S($C$39:$C$284) -> 0.58776063 | H35: =_xlfn.COVARIANCE.S($C$39:$C$284,I39:I284)/_xlfn.VAR.S($C$39:$C$284) -> 0.53479868 | K35: =_xlfn.COVARIANCE.S($C$39:$C$284,L39:L284)/_xlfn.VAR.S($C$39:$C$284) -> 0.48002386 | N35: =_xlfn.COVARIANCE.S($C$39:$C$284,O39:O284)/_xlfn.VAR.S($C$39:$C$284) -> 0.69768926
A37: Date | B37: Price | C37: Returns | E37: Price | F37: Returns | H37: Price | I37: Returns | K37: Price | L37: Returns | N37: Price | O37: Returns
A39: 43990 | B39: 11867.17 | E39: 39.966343 | H39: 25.548868 | K39: 115.19059 | N39: 34.150002
A40: 43997 | B40: 11980.12 | C40: =B40/B39-1 -> 0.0095178712 | E40: 40.700893 | F40: =E40/E39-1 -> 0.018379215 | H40: 26.084921 | I40: =H40/H39-1 -> 0.020981478 | K40: 117.22652 | L40: =K40/K39-1 -> 0.017674421 | N40: 35.040001 | O40: =N40/N39-1 -> 0.026061463
A41: 44004 | B41: 11604.43 | C41: =B41/B40-1 -> -0.031359488 | E41: 38.534073 | F41: =E41/E40-1 -> -0.053237653 | H41: 25.639721 | I41: =H41/H40-1 -> -0.017067332 | K41: 115.12807 | L41: =K41/K40-1 -> -0.017900813 | N41: 33.950001 | O41: =N41/N40-1 -> -0.031107305
A42: 44011 | B42: 11991.52 | C42: =B42/B41-1 -> 0.033357076 | E42: 39.692646 | F42: =E42/E41-1 -> 0.030066196 | H42: 25.921379 | I42: =H42/H41-1 -> 0.010985221 | K42: 118.62843 | L42: =K42/K41-1 -> 0.030404046 | N42: 34.630001 | O42: =N42/N41-1 -> 0.020029454
A43: 44018 | B43: 12075.58 | C43: =B43/B42-1 -> 0.0070099996 | E43: 39.93145 | F43: =E43/E42-1 -> 0.0060163286 | H43: 26.670986 | I43: =H43/H42-1 -> 0.028918485 | K43: 120.0661 | L43: =K43/K42-1 -> 0.012119144 | N43: 35.825001 | O43: =N43/N42-1 -> 0.034507651
A44: 44025 | B44: 12402.74 | C44: =B44/B43-1 -> 0.027092707 | E44: 41.408428 | F44: =E44/E43-1 -> 0.036987838 | H44: 27.20075 | I44: =H44/H43-1 -> 0.019862933 | K44: 120.24468 | L44: =K44/K43-1 -> 0.0014872974 | N44: 37.110001 | O44: =N44/N43-1 -> 0.035868806
A45: 44032 | B45: 12461.78 | C45: =B45/B44-1 -> 0.0047602415 | E45: 42.885391 | F45: =E45/E44-1 -> 0.035668174 | H45: 27.712248 | I45: =H45/H44-1 -> 0.018804555 | K45: 121.49482 | L45: =K45/K44-1 -> 0.010396677 | N45: 37.439999 | O45: =N45/N44-1 -> 0.0088924277
A46: 44039 | B46: 12465.05 | C46: =B46/B45-1 -> 0.00026236476 | E46: 41.779881 | F46: =E46/E45-1 -> -0.025778242 | H46: 27.940601 | I46: =H46/H45-1 -> 0.0082401471 | K46: 122.92351 | L46: =K46/K45-1 -> 0.01175925 | N46: 39.240002 | O46: =N46/N45-1 -> 0.048077004
A47: 44046 | B47: 12765.84 | C47: =B47/B46-1 -> 0.024130673 | E47: 42.275146 | F47: =E47/E46-1 -> 0.011854151 | H47: 27.063744 | I47: =H47/H46-1 -> -0.031382897 | K47: 122.10201 | L47: =K47/K46-1 -> -0.0066829772 | N47: 41.595001 | O47: =N47/N46-1 -> 0.060015262
A48: 44053 | B48: 12902.5 | C48: =B48/B47-1 -> 0.010705144 | E48: 42.850021 | F48: =E48/E47-1 -> 0.013598415 | H48: 27.301226 | I48: =H48/H47-1 -> 0.008774913 | K48: 122.83422 | L48: =K48/K47-1 -> 0.0059966907 | N48: 41.66 | O48: =N48/N47-1 -> 0.0015626637
A49: 44060 | B49: 12809.07 | C49: =B49/B48-1 -> -0.0072412081 | E49: 41.815247 | F49: =E49/E48-1 -> -0.02414874 | H49: 26.424368 | I49: =H49/H48-1 -> -0.032117898 | K49: 121.85198 | L49: =K49/K48-1 -> -0.0079964605 | N49: 41.365002 | O49: =N49/N48-1 -> -0.007081085
A50: 44067 | B50: 13170.96 | C50: =B50/B49-1 -> 0.028252608 | E50: 44.070518 | F50: =E50/E49-1 -> 0.053934179 | H50: 27.465635 | I50: =H50/H49-1 -> 0.039405559 | K50: 124.95945 | L50: =K50/K49-1 -> 0.02550199 | N50: 42.27 | O50: =N50/N49-1 -> 0.02187835
A51: 44074 | B51: 12966.14 | C51: =B51/B50-1 -> -0.015550902 | E51: 45.140663 | F51: =E51/E50-1 -> 0.02428256 | H51: 26.981537 | I51: =H51/H50-1 -> -0.017625589 | K51: 123.90575 | L51: =K51/K50-1 -> -0.0084323034 | N51: 41.134998 | O51: =N51/N50-1 -> -0.026851242
... A284: 45705 | B284: 20228.2 | C284: =B284/B283-1 -> 0.0048538312 | E284: 69.56 | F284: =E284/E283-1 -> 0.017405295 | H284: 32.56 | I284: =H284/H283-1 -> 0.03562341 | K284: 144.53 | L284: =K284/K283-1 -> 0.016885949 | N284: 51.69 | O284: =N284/N283-1 -> 0.049543147

Sheet Cost of debt
A2: Particulars
B3: Unit
A5: Cost of debt
A6: Marginal tax rate | B6: ='Cost of equity'!B14 -> 0.27
A7: Market based method
A8: Yield of Coca-Cola Bond
A9: FV | B9: 100
A10: CMP | B10: 123.605
A11: Redempetion | B11: 70704
A12: Valuation date | B12: 45708
A13: Time to maturity | B13: =YEARFRAC(B11,B12,0) -> 68.441667
A14: Coupon rate | B14: 0.07375
A15: Coupon amount | B15: =B14*B9 -> 7.375
A16: Cost of debt. (Pre tax) | B16: =RATE(B13,B15,-B10,B9,0) -> 0.059443472
A17: Cost of debt. (Post tax) | B17: =B16*(1-$B$6) -> 0.043393735
A19: Premium based method
A20: Risk free rate | B20: ='Cost of equity'!B6 -> 0.04506
A21: Risk premium | B21: 0.0077
A22: Cost of debt. (Pre tax) | B22: =B20+B21 -> 0.05276
A23: Cost of debt. (Post tax) | B23: =B22*(1-$B$6) -> 0.0385148

Sheet CFS
E1: (In millions except par value)
A2: Particulars | C2: Forecast
B3: Unit | C3: 2025 | D3: =C3+1 -> 2026 | E3: =D3+1 -> 2027 | F3: =E3+1 -> 2028 | G3: =F3+1 -> 2029
B4: $
A5: Cash flow form operations
A6: Net profit | C6: ='P&L'!H38 -> 13370.593 | D6: ='P&L'!I38 -> 14978.657 | E6: ='P&L'!J38 -> 16915.182 | F6: ='P&L'!K38 -> 18977.2 | G6: ='P&L'!L38 -> 21064.863
A7: Add/Less : Non Cash items
A8: Depreciation and amortization | C8: ='P&L'!H57 -> 1122.3584 | D8: ='P&L'!I57 -> 1187.1028 | E8: ='P&L'!J57 -> 1246.7465 | F8: ='P&L'!K57 -> 1316.6385 | G8: ='P&L'!L57 -> 1327.9671
A9: Interest expenses | C9: ='P&L'!H26 -> 1560.4486 | D9: ='P&L'!I26 -> 1290.1201 | E9: ='P&L'!J26 -> 1185.3863 | F9: ='P&L'!K26 -> 1058.9704 | G9: ='P&L'!L26 -> 887.43926
A10: Interest income | C10: =-'P&L'!H23 -> -696.8251 | D10: =-'P&L'!I23 -> -464.12855 | E10: =-'P&L'!J23 -> -755.93948 | F10: =-'P&L'!K23 -> -1048.61 | G10: =-'P&L'!L23 -> -1271.773
A11: Equity income | C11: =-'P&L'!H29 -> -1976.0156 | D11: =-'P&L'!I29 -> -2199.4152 | E11: =-'P&L'!J29 -> -2433.9862 | F11: =-'P&L'!K29 -> -2676.2388 | G11: =-'P&L'!L29 -> -2921.9808
A12: Other Income | C12: =-'P&L'!H32 -> -81.6 | D12: =-'P&L'!I32 -> -74.52 | E12: =-'P&L'!J32 -> -16.024 | F12: =-'P&L'!K32 -> -22.6288 | G12: =-'P&L'!L32 -> -54.75456
A13: Cash flow form operations before working capital changes | C13: =SUM(C6:C12) -> 13298.959 | D13: =SUM(D6:D12) -> 14717.816 | E13: =SUM(E6:E12) -> 16141.365 | F13: =SUM(F6:F12) -> 17605.331 | G13: =SUM(G6:G12) -> 19031.761
A14: Changes in Working capital
A15: Trade receivable | C15: =-('Balance Sheet'!H11-'Balance Sheet'!G11) -> -357.16911 | D15: =-('Balance Sheet'!I11-'Balance Sheet'!H11) -> -381.46727 | E15: =-('Balance Sheet'!J11-'Balance Sheet'!I11) -> -390.35215 | F15: =-('Balance Sheet'!K11-'Balance Sheet'!J11) -> -391.64883 | G15: =-('Balance Sheet'!L11-'Balance Sheet'!K11) -> -384.43834
A16: Inventory | C16: =-('Balance Sheet'!H12-'Balance Sheet'!G12) -> -710.72734 | D16: =-('Balance Sheet'!I12-'Balance Sheet'!H12) -> -614.87853 | E16: =-('Balance Sheet'!J12-'Balance Sheet'!I12) -> -645.62656 | F16: =-('Balance Sheet'!K12-'Balance Sheet'!J12) -> -666.76881 | G16: =-('Balance Sheet'!L12-'Balance Sheet'!K12) -> -676.37321
A17: Prepaid expenses and other current assets | C17: =-('Balance Sheet'!H13-'Balance Sheet'!G13) -> -391.9793 | D17: =-('Balance Sheet'!I13-'Balance Sheet'!H13) -> -398.06639 | E17: =-('Balance Sheet'!J13-'Balance Sheet'!I13) -> -417.97237 | F17: =-('Balance Sheet'!K13-'Balance Sheet'!J13) -> -431.65966 | G17: =-('Balance Sheet'!L13-'Balance Sheet'!K13) -> -437.87745
A18: Accounts payable and accrued expenses | C18: =('Balance Sheet'!H29-'Balance Sheet'!G29) -> 3360.0547 | D18: =('Balance Sheet'!I29-'Balance Sheet'!H29) -> 2834.8751 | E18: =('Balance Sheet'!J29-'Balance Sheet'!I29) -> 2976.6378 | F18: =('Balance Sheet'!K29-'Balance Sheet'!J29) -> 3074.1134 | G18: =('Balance Sheet'!L29-'Balance Sheet'!K29) -> 3118.3941
A19: Accrued income taxes | C19: =('Balance Sheet'!H32-'Balance Sheet'!G32) -> -3.6381697 | D19: =('Balance Sheet'!I32-'Balance Sheet'!H32) -> 206.37634 | E19: =('Balance Sheet'!J32-'Balance Sheet'!I32) -> 329.78363 | F19: =('Balance Sheet'!K32-'Balance Sheet'!J32) -> 245.76748 | G19: =('Balance Sheet'!L32-'Balance Sheet'!K32) -> 154.9495
A20: Cash generated from operations | C20: =SUM(C13:C19) -> 15195.5 | D20: =SUM(D13:D19) -> 16364.655 | E20: =SUM(E13:E19) -> 17993.835 | F20: =SUM(F13:F19) -> 19435.134 | G20: =SUM(G13:G19) -> 20806.416
A22: Cashflow from Investing activities
A23: Purchase of Property plant and equipment | C23: =-Capex!G7 -> -1404 | D23: =-Capex!H7 -> -1282.8424 | E23: =-Capex!I7 -> -1430.0678 | F23: =-Capex!J7 -> -1428.0583 | G23: =-Capex!K7 -> -1393.1438
A24: Purchase of Intangible assets | C24: =-Capex!G24 -> 0 | D24: =-Capex!H24 -> 0 | E24: =-Capex!I24 -> 0 | F24: =-Capex!J24 -> 0 | G24: =-Capex!K24 -> 0
A25: Interset income | C25: =-C10 -> 696.8251 | D25: =-D10 -> 464.12855 | E25: =-E10 -> 755.93948 | F25: =-F10 -> 1048.61 | G25: =-G10 -> 1271.773
A26: Equity income | C26: =-C11 -> 1976.0156 | D26: =-D11 -> 2199.4152 | E26: =-E11 -> 2433.9862 | F26: =-F11 -> 2676.2388 | G26: =-G11 -> 2921.9808
A27: Other Income | C27: =-C12 -> 81.6 | D27: =-D12 -> 74.52 | E27: =-E12 -> 16.024 | F27: =-F12 -> 22.6288 | G27: =-G12 -> 54.75456
A28: Cash generated from investments | C28: =SUM(C23:C27) -> 1350.4407 | D28: =SUM(D23:D27) -> 1455.2213 | E28: =SUM(E23:E27) -> 1775.8819 | F28: =SUM(F23:F27) -> 2319.4193 | G28: =SUM(G23:G27) -> 2855.3646
A30: Cashflow from Financing activities
A31: Debt Taken | C31: =Debt!C7+Debt!C19 -> -10559.6 | D31: =Debt!D7+Debt!D19 -> -1850.7824 | E31: =Debt!E7+Debt!E19 -> -1112.6552 | F31: =Debt!F7+Debt!F19 -> 485.49612 | G31: =Debt!G7+Debt!G19 -> -2669.7785
A32: Debt repaid | C32: =-Debt!C8-Debt!C20 -> -2154.1596 | D32: =-Debt!D8-Debt!D20 -> -1171.7654 | E32: =-Debt!E8-Debt!E20 -> -1911.8307 | F32: =-Debt!F8-Debt!F20 -> -4759.9143 | G32: =-Debt!G8-Debt!G20 -> -2959.5318
A33: Interest paid | C33: =-C9 -> -1560.4486 | D33: =-D9 -> -1290.1201 | E33: =-E9 -> -1185.3863 | F33: =-F9 -> -1058.9704 | G33: =-G9 -> -887.43926
A34: Dividend | C34: =-'P&L'!H59 -> -9685.1352 | D34: =-'P&L'!I59 -> -10849.954 | E34: =-'P&L'!J59 -> -12252.697 | F34: =-'P&L'!K59 -> -13746.342 | G34: =-'P&L'!L59 -> -15258.564
A35: Cash generated from financing activity | C35: =SUM(C31:C34) -> -23959.343 | D35: =SUM(D31:D34) -> -15162.622 | E35: =SUM(E31:E34) -> -16462.569 | F35: =SUM(F31:F34) -> -19079.731 | G35: =SUM(G31:G34) -> -21775.314
A37: Total cash generated during year | C37: =C20+C28+C35 -> -7413.4027 | D37: =D20+D28+D35 -> 2657.2548 | E37: =E20+E28+E35 -> 3307.1481 | F37: =F20+F28+F35 -> 2674.823 | G37: =G20+G28+G35 -> 1886.4666
A39: Add: Opening balance of cash and cash equivalents | C39: ='Balance Sheet'!G6 -> 10828 | D39: ='Balance Sheet'!H6 -> 3414.5973 | E39: ='Balance Sheet'!I6 -> 6071.852 | F39: ='Balance Sheet'!J6 -> 9379.0001 | G39: ='Balance Sheet'!K6 -> 12053.823
A40: Closing balance | C40: =C37+C39 -> 3414.5973 | D40: =D37+D39 -> 6071.852 | E40: =E37+E39 -> 9379.0001 | F40: =F37+F39 -> 12053.823 | G40: =G37+G39 -> 13940.29

Sheet Balance Sheet
I1: (In millions except par value)
A2: Particulars | C2: Historical | H2: Forecast
B3: Unit | C3: 2020 | D3: =C3+1 -> 2021 | E3: =D3+1 -> 2022 | F3: =E3+1 -> 2023 | G3: =F3+1 -> 2024 | H3: =G3+1 -> 2025 | I3: =H3+1 -> 2026 | J3: =I3+1 -> 2027 | K3: =J3+1 -> 2028 | L3: =K3+1 -> 2029
A4: Assets | B4: $
A5: Current Assets
A6: Cash and cash equivalents | C6: 6795 | D6: 9684 | E6: 9519 | F6: 9366 | G6: 10828 | H6: =CFS!C40 -> 3414.5973 | I6: =CFS!D40 -> 6071.852 | J6: =CFS!E40 -> 9379.0001 | K6: =CFS!F40 -> 12053.823 | L6: =CFS!G40 -> 13940.29
A7: Short-term investments | C7: 1771 | D7: 1242 | E7: 1043 | F7: 2997 | G7: 2020 | H7: =G7 -> 2020 | I7: =H7 -> 2020 | J7: =I7 -> 2020 | K7: =J7 -> 2020 | L7: =K7 -> 2020
A8: Total Cash, Cash Equivalents and Short-Term Investments | C8: =SUM(C6:C7) -> 8566 | D8: =SUM(D6:D7) -> 10926 | E8: =SUM(E6:E7) -> 10562 | F8: =SUM(F6:F7) -> 12363 | G8: =SUM(G6:G7) -> 12848 | H8: =SUM(H6:H7) -> 5434.5973 | I8: =SUM(I6:I7) -> 8091.852 | J8: =SUM(J6:J7) -> 11399 | ... L8: =SUM(L6:L7) -> 15960.29
A10: Marketable securities | C10: 2348 | D10: 1699 | E10: 1069 | F10: 1300 | G10: 1723 | H10: =G10 -> 1723 | I10: =H10 -> 1723 | J10: =I10 -> 1723 | K10: =J10 -> 1723 | L10: =K10 -> 1723
A11: Trade accounts receivable, | C11: 3144 | D11: 3512 | E11: 3487 | F11: 3410 | G11: 3569 | H11: =H47 -> 3926.1691 | I11: =I47 -> 4307.6364 | J11: =J47 -> 4697.9885 | K11: =K47 -> 5089.6374 | L11: =L47 -> 5474.0757
A12: Inventories | C12: 3266 | D12: 3414 | E12: 4233 | F12: 4424 | G12: 4728 | H12: =H51 -> 5438.7273 | I12: =I51 -> 6053.6059 | J12: =J51 -> 6699.2324 | K12: =K51 -> 7366.0012 | L12: =L51 -> 8042.3744
A13: Prepaid expenses and other current assets | C13: 1916 | D13: 2994 | E13: 3240 | F13: 5235 | G13: 3129 | H13: =H56 -> 3520.9793 | I13: =I56 -> 3919.0457 | J13: =J56 -> 4337.0181 | K13: =K56 -> 4768.6777 | L13: =L56 -> 5206.5552
A14: Total Current Assets | C14: =SUM(C8:C13) -> 19240 | D14: =SUM(D8:D13) -> 22545 | E14: =SUM(E8:E13) -> 22591 | F14: =SUM(F8:F13) -> 26732 | G14: =SUM(G8:G13) -> 25997 | H14: =SUM(H8:H13) -> 20043.473 | I14: =SUM(I8:I13) -> 24095.14 | J14: =SUM(J8:J13) -> 28856.239 | ... L14: =SUM(L8:L13) -> 36406.295
A16: Equity method investments | C16: 19273 | D16: 17598 | E16: 18264 | F16: 19671 | G16: 18087 | H16: =G16 -> 18087 | I16: =H16 -> 18087 | J16: =I16 -> 18087 | K16: =J16 -> 18087 | L16: =K16 -> 18087
A17: Other investments | C17: 812 | D17: 818 | E17: 501 | F17: 118 | G17: 0 | H17: =G17 -> 0 | I17: =H17 -> 0 | J17: =I17 -> 0 | K17: =J17 -> 0 | L17: =K17 -> 0
A18: Other noncurrent assets | C18: 6184 | D18: 6731 | E18: 6189 | F18: 7162 | G18: 13403 | H18: =G18 -> 13403 | I18: =H18 -> 13403 | J18: =I18 -> 13403 | K18: =J18 -> 13403 | L18: =K18 -> 13403
A19: Deferred income tax assets | C19: 2460 | D19: 2129 | E19: 1746 | F19: 1561 | G19: 1319 | H19: =G19 -> 1319 | I19: =H19 -> 1319 | J19: =I19 -> 1319 | K19: =J19 -> 1319 | L19: =K19 -> 1319
A20: Property, plant and equipment (net) | C20: 10777 | D20: 9920 | E20: 9841 | F20: 9236 | G20: 10303 | H20: =Capex!H10 -> 10524.484 | I20: =Capex!I10 -> 10821.449 | J20: =Capex!J10 -> 11044.761 | K20: =Capex!K10 -> 11163.266 | L20: =Capex!L10 -> 10254.572
A21: Trademarks with indefinite lives | C21: 10395 | D21: 14465 | E21: 14214 | F21: 14349 | G21: 13301 | H21: =G21 -> 13301 | I21: =H21 -> 13301 | J21: =I21 -> 13301 | K21: =J21 -> 13301 | L21: =K21 -> 13301
A22: Goodwill | C22: 17506 | D22: 19363 | E22: 18782 | F22: 18358 | G22: 18139 | H22: =G22 -> 18139 | I22: =H22 -> 18139 | J22: =I22 -> 18139 | K22: =J22 -> 18139 | L22: =K22 -> 18139
A23: Forecasting Adjustment – Non-operating Asset | C23: 0 | D23: 0 | E23: 0 | F23: 0 | G23: 0 | H23: =H41-H55 -> 7520.1576 | I23: =I41-I55 -> 5742.9322 | J23: =J41-J55 -> 3678.9417 | K23: =K41-K55 -> 8365.8562 | L23: =L41-L55 -> 10297.727
A24: Other intangible assets | C24: 649 | D24: 785 | E24: 635 | F24: 516 | G24: 0 | H24: =Capex!H18 -> 377 | I24: =Capex!I18 -> 323 | J24: =Capex!J18 -> 281 | K24: =Capex!K18 -> 239 | L24: =Capex!L18 -> 205
A25: Total assets | C25: =C14+SUM(C16:C24) -> 87296 | D25: =D14+SUM(D16:D24) -> 94354 | E25: =E14+SUM(E16:E24) -> 92763 | F25: =F14+SUM(F16:F24) -> 97703 | G25: =G14+SUM(G16:G24) -> 100549 | H25: =H14+SUM(H16:H24) -> 102714.11 | I25: =I14+SUM(I16:I24) -> 105231.52 | J25: =J14+SUM(J16:J24) -> 108109.94 | ... L25: =L14+SUM(L16:L24) -> 121412.59
A27: Equity and Liabilities
A28: Current Liabilities
A29: Accounts payable and accrued expenses | C29: 11145 | D29: 14619 | E29: 15749 | F29: 15485 | G29: 21715 | H29: =H60 -> 25075.055 | I29: =I60 -> 27909.93 | J29: =J60 -> 30886.568 | K29: =K60 -> 33960.681 | L29: =L60 -> 37079.075
A30: Loans and notes payable | C30: 2183 | D30: 3307 | E30: 2373 | F30: 4557 | G30: 1499 | H30: =Debt!C21 -> 1304.8404 | I30: =Debt!D21 -> 1203.075 | J30: =Debt!E21 -> 1101.2444 | K30: =Debt!F21 -> 957.33007 | L30: =Debt!G21 -> 767.79823
A31: Current maturities of long-term debt | C31: 485 | D31: 1338 | E31: 399 | F31: 1960 | G31: 648 | H31: =Debt!C8 -> 1960 | I31: =Debt!D8 -> 1070 | J31: =Debt!E8 -> 1810 | K31: =Debt!F8 -> 4616 | L31: =Debt!G8 -> 2770
A32: Accrued income taxes | C32: 788 | D32: 686 | E32: 1203 | F32: 1569 | G32: 1387 | H32: =H63 -> 1383.3618 | I32: =I63 -> 1589.7382 | J32: =J63 -> 1919.5218 | K32: =K63 -> 2165.2893 | L32: =L63 -> 2320.2388
A33: Total Current Liabilities | C33: =SUM(C29:C32) -> 14601 | D33: =SUM(D29:D32) -> 19950 | E33: =SUM(E29:E32) -> 19724 | F33: =SUM(F29:F32) -> 23571 | G33: =SUM(G29:G32) -> 25249 | H33: =SUM(H29:H32) -> 29723.257 | I33: =SUM(I29:I32) -> 31772.743 | J33: =SUM(J29:J32) -> 35717.334 | ... L33: =SUM(L29:L32) -> 42937.112
A34: Long-term debt | C34: 40125 | D34: 38116 | E34: 36377 | F34: 35547 | G34: 42375 | H34: =(Debt!C9-Debt!D8) -> 36380.4 | I34: =(Debt!D9-Debt!E8) -> 32719.618 | J34: =(Debt!E9-Debt!F8) -> 26990.962 | K34: =(Debt!F9-Debt!G8) -> 24706.459 | L34: =(Debt!G9-Debt!H8) -> 22036.68
A35: Other noncurrent liabilities | C35: 9453 | D35: 8607 | E35: 7922 | F35: 8466 | G35: 4084 | H35: =G35 -> 4084 | I35: =H35 -> 4084 | J35: =I35 -> 4084 | K35: =J35 -> 4084 | L35: =K35 -> 4084
A36: Deferred income tax liabilities | C36: 1833 | D36: 2821 | E36: 2914 | F36: 2639 | G36: 2469 | H36: =G36 -> 2469 | I36: =H36 -> 2469 | J36: =I36 -> 2469 | K36: =J36 -> 2469 | L36: =K36 -> 2469
A38: Equity | C38: 19299 | D38: 22999 | E38: 24105 | F38: 25941 | G38: 24856 | H38: =G38+'P&L'!H40-'P&L'!H59 -> 28517.601 | I38: =H38+'P&L'!I40-'P&L'!I59 -> 32619.579 | J38: =I38+'P&L'!J40-'P&L'!J59 -> 37251.883 | K38: =J38+'P&L'!K40-'P&L'!K59 -> 42448.881 | L38: =K38+'P&L'!L40-'P&L'!L59 -> 48217.595
A39: Noncontrolling interests | C39: 1985 | D39: 1861 | E39: 1721 | F39: 1539 | G39: 1516 | H39: =G39+'P&L'!H39 -> 1539.8563 | I39: =H39+'P&L'!I39 -> 1566.5817 | J39: =I39+'P&L'!J39 -> 1596.7623 | K39: =J39+'P&L'!K39 -> 1630.6221 | L39: =K39+'P&L'!L39 -> 1668.2067
A40: Total Equity | C40: =C38+C39 -> 21284 | D40: =D38+D39 -> 24860 | E40: =E38+E39 -> 25826 | F40: =F38+F39 -> 27480 | G40: =G38+G39 -> 26372 | H40: =H38+H39 -> 30057.458 | I40: =I38+I39 -> 34186.161 | J40: =J38+J39 -> 38848.645 | ... L40: =L38+L39 -> 49885.802
A41: Total Liabilities and Equity | C41: =C40+SUM(C33:C36) -> 87296 | D41: =D40+SUM(D33:D36) -> 94354 | E41: =E40+SUM(E33:E36) -> 92763 | F41: =F40+SUM(F33:F36) -> 97703 | G41: =G40+SUM(G33:G36) -> 100549 | H41: =H40+SUM(H33:H36) -> 102714.11 | I41: =I40+SUM(I33:I36) -> 105231.52 | J41: =J40+SUM(J33:J36) -> 108109.94 | ... L41: =L40+SUM(L33:L36) -> 121412.59
A43: Check | C43: =C41-C25 -> 0 | D43: =D41-D25 -> 0 | E43: =E41-E25 -> 0 | F43: =F41-F25 -> 0 | G43: =G41-G25 -> 0
A45: Workings
A46: Current assets
...

Sheet Debt
E1: (In millions except par value)
A2: Particulars | C2: Forecast
B3: Unit | C3: 2025 | D3: =C3+1 -> 2026 | E3: =D3+1 -> 2027 | F3: =E3+1 -> 2028 | G3: =F3+1 -> 2029
B4: $
A5: Long-term debt
A6: Opening balance | C6: 49970 | D6: =C9 -> 37450.4 | E6: =D9 -> 34529.618 | F6: =E9 -> 31606.962 | G6: =F9 -> 27476.459
A7: Add:Loan taken | C7: =C9+C8-C6 -> -10559.6 | D7: =D9+D8-D6 -> -1850.7824 | E7: =E9+E8-E6 -> -1112.6552 | F7: =F9+F8-F6 -> 485.49612 | G7: =G9+G8-G6 -> -2669.7785
A8: Less: Loan repaid | C8: =1960 -> 1960 | D8: 1070 | E8: 1810 | F8: 4616 | G8: 2770
A9: Closing balance | C9: =C15*'P&L'!G56 -> 37450.4 | D9: =D15*'P&L'!H56 -> 34529.618 | E9: =E15*'P&L'!I56 -> 31606.962 | F9: =F15*'P&L'!J56 -> 27476.459 | G9: =G15*'P&L'!K56 -> 22036.68
A11: Average Interest rate | C11: =3.4% -> 0.034 | D11: =3.4% -> 0.034 | E11: =3.4% -> 0.034 | F11: =3.4% -> 0.034 | G11: =3.4% -> 0.034
A13: Interest expenses | C13: =AVERAGE(C9,C6)*C11 -> 1486.1468 | D13: =AVERAGE(D9,D6)*D11 -> 1223.6603 | E13: =AVERAGE(E9,E6)*E11 -> 1124.3219 | F13: =AVERAGE(F9,F6)*F11 -> 1004.4182 | G13: =AVERAGE(G9,G6)*G11 -> 841.72336
A15: Total Long term debt/EBITDA | C15: ='Balance Sheet'!H66 -> 2.470343 | D15: ='Balance Sheet'!I66 -> 2.1027573 | E15: ='Balance Sheet'!J66 -> 1.7351715 | F15: ='Balance Sheet'!K66 -> 1.3675858 | G15: ='Balance Sheet'!L66 -> 1
A17: Loans and notes payable
A18: Opening balance | C18: ='Balance Sheet'!G30 -> 1499 | D18: =C21 -> 1304.8404 | E18: =D21 -> 1203.075 | F18: =E21 -> 1101.2444 | G18: =F21 -> 957.33007
A19: Add:Loan taken | C19: =IF(C21>C18,C21-C18,0) -> 0 | D19: =IF(D21>D18,D21-D18,0) -> 0 | E19: =IF(E21>E18,E21-E18,0) -> 0 | F19: =IF(F21>F18,F21-F18,0) -> 0 | G19: =IF(G21>G18,G21-G18,0) -> 0
A20: Less: Loan repaid | C20: =IF(C21<C18,C18-C21,0) -> 194.15958 | D20: =IF(D21<D18,D18-D21,0) -> 101.7654 | E20: =IF(E21<E18,E18-E21,0) -> 101.83065 | F20: =IF(F21<F18,F18-F21,0) -> 143.91431 | G20: =IF(G21<G18,G18-G21,0) -> 189.53183
A21: Closing balance | C21: =C9*'Balance Sheet'!G67 -> 1304.8404 | D21: =D9*'Balance Sheet'!H67 -> 1203.075 | E21: =E9*'Balance Sheet'!I67 -> 1101.2444 | F21: =F9*'Balance Sheet'!J67 -> 957.33007 | G21: =G9*'Balance Sheet'!K67 -> 767.79823
A24: Average Interest rate | C24: 0.053 | D24: 0.053 | E24: 0.053 | F24: 0.053 | G24: 0.053
A26: Interest expenses | C26: =C24*AVERAGE(C21,C18) -> 74.301771 | D26: =D24*AVERAGE(D21,D18) -> 66.459759 | E26: =E24*AVERAGE(E21,E18) -> 61.064464 | F26: =F24*AVERAGE(F21,F18) -> 54.552223 | G26: =G24*AVERAGE(G21,G18) -> 45.7159

Sheet Capex
I1: (In millions except par value)
A2: Particulars | C2: Historical | H2: Forecast
B3: Unit | C3: 2020 | D3: =C3+1 -> 2021 | E3: =D3+1 -> 2022 | F3: =E3+1 -> 2023 | G3: =F3+1 -> 2024 | H3: =G3+1 -> 2025 | I3: =H3+1 -> 2026 | J3: =I3+1 -> 2027 | K3: =J3+1 -> 2028 | L3: =K3+1 -> 2029
A5: Property plant and equipment
A6: Opening Gross block | C6: =18921 -> 18921 | D6: =C8 -> 19700 | E6: =D8 -> 18862 | F6: =E8 -> 19075 | G6: =F8 -> 18469 | H6: =G8 -> 19873 | I6: =H8 -> 21155.842 | J6: =I8 -> 22585.91 | K6: =J8 -> 24013.968 | L6: =K8 -> 25407.112
A7: Add:Net purchases | B7: $ | C7: =C8-C6 -> 779 | D7: =D8-D6 -> -838 | E7: =E8-E6 -> 213 | F7: =F8-F6 -> -606 | G7: =G8-G6 -> 1404 | H7: =H8-H6 -> 1282.8424 | I7: =I8-I6 -> 1430.0678 | J7: =J8-J6 -> 1428.0583 | ... L7: =L8-L6 -> 385.27284
A8: Closing Gross block | C8: =C9+C10 -> 19700 | D8: =D9+D10 -> 18862 | E8: =E9+E10 -> 19075 | F8: =F9+F10 -> 18469 | G8: =G9+G10 -> 19873 | H8: ='P&L'!H7/Capex!H15 -> 21155.842 | I8: ='P&L'!I7/Capex!I15 -> 22585.91 | J8: ='P&L'!J7/Capex!J15 -> 24013.968 | K8: ='P&L'!K7/Capex!K15 -> 25407.112 | L8: ='P&L'!L7/Capex!L15 -> 25792.385
A9: Less: Accumulated depreciation | C9: 8923 | D9: 8942 | E9: 9234 | F9: 9233 | G9: 9570 | H9: =G9+H12 -> 10631.358 | I9: =H9+I12 -> 11764.461 | J9: =I9+J12 -> 12969.208 | K9: =J9+K12 -> 14243.846 | L9: =K9+L12 -> 15537.813
A10: Net block | C10: ='Balance Sheet'!C20 -> 10777 | D10: ='Balance Sheet'!D20 -> 9920 | E10: ='Balance Sheet'!E20 -> 9841 | F10: ='Balance Sheet'!F20 -> 9236 | G10: ='Balance Sheet'!G20 -> 10303 | H10: =H8-H9 -> 10524.484 | I10: =I8-I9 -> 10821.449 | J10: =J8-J9 -> 11044.761 | K10: =K8-K9 -> 11163.266 | L10: =L8-L9 -> 10254.572
A12: Depreciation | C12: 1301 | D12: 1262 | E12: 1125 | F12: 1018 | G12: 997 | H12: =H8*H14 -> 1061.3584 | I12: =I8*I14 -> 1133.1028 | J12: =J8*J14 -> 1204.7465 | K12: =K8*K14 -> 1274.6385 | L12: =L8*L14 -> 1293.9671
A13: Depreciation & amortization | C13: ='P&L'!C57 -> 1536 | D13: ='P&L'!D57 -> 1452 | E13: ='P&L'!E57 -> 1260 | F13: ='P&L'!F57 -> 1128 | G13: ='P&L'!G57 -> 1075 | H13: =H12+H29 -> 1122.3584 | I13: =I12+I29 -> 1187.1028 | J13: =J12+J29 -> 1246.7465 | K13: =K12+K29 -> 1316.6385 | L13: =L12+L29 -> 1327.9671
A14: Rate of depreciation | C14: =C12/C8 -> 0.066040609 | D14: =D12/D8 -> 0.066907009 | E14: =E12/E8 -> 0.05897772 | F14: =F12/F8 -> 0.055119389 | G14: =G12/G8 -> 0.05016857 | H14: =G14 -> 0.05016857 | I14: =H14 -> 0.05016857 | J14: =I14 -> 0.05016857 | K14: =J14 -> 0.05016857 | L14: =K14 -> 0.05016857
A15: FATR | C15: =Revenue!C45/Capex!C8 -> 1.6758376 | D15: =Revenue!D45/Capex!D8 -> 2.0493585 | E15: =Revenue!E45/Capex!E8 -> 2.2544692 | F15: =Revenue!F45/Capex!F8 -> 2.4773404 | G15: =Revenue!G45/Capex!G8 -> 2.3680874 | H15: =G15+($L$15-$H$15)/5 -> 2.4734061 | I15: =H15+($L$15-$H$15)/5 -> 2.5787249 | J15: =I15+($L$15-$H$15)/5 -> 2.6840437 | K15: =J15+($L$15-$H$15)/5 -> 2.7893625 | L15: 3
A18: Other Intangible assets | C18: ='Balance Sheet'!C24 -> 649 | D18: ='Balance Sheet'!D24 -> 785 | E18: ='Balance Sheet'!E24 -> 635 | F18: ='Balance Sheet'!F24 -> 516 | G18: =G19+G20 -> 438 | H18: =H19+H20 -> 377 | I18: =I19+I20 -> 323 | J18: =J19+J20 -> 281 | K18: =K19+K20 -> 239 | L18: =L19+L20 -> 205
A19: Other Intangible assets (With indefinite life) | C19: 225 | D19: 211 | E19: 175 | F19: 161 | G19: =F19 -> 161 | H19: =G19 -> 161 | I19: =H19 -> 161 | J19: =I19 -> 161 | K19: =J19 -> 161 | L19: =K19 -> 161
A20: Other Intangible assets (With Definite life) | C20: =C18-C19 -> 424 | D20: =D18-D19 -> 574 | E20: =E18-E19 -> 460 | F20: =F18-F19 -> 355 | G20: =G27 -> 277 | H20: =H27 -> 216 | I20: =I27 -> 162 | J20: =J27 -> 120 | K20: =K27 -> 78 | L20: =L27 -> 44
A22: Other Intangible assets (With definite life)
A23: Opening balance | C23: 917 | D23: =C25 -> 772 | E23: =D25 -> 798 | F23: =E25 -> 707 | G23: 562 | H23: =F25 -> 562 | I23: =H25 -> 562 | J23: =I25 -> 562 | K23: =J25 -> 562 | L23: =K25 -> 562
A24: Add:Net purchases | C24: =C25-C23 -> -145 | D24: =D25-D23 -> 26 | E24: =E25-E23 -> -91 | F24: =F25-F23 -> -145 | G24: =0 -> 0 | H24: =0 -> 0 | I24: =0 -> 0 | J24: =0 -> 0 | K24: =0 -> 0 | L24: =0 -> 0
A25: Gross block | C25: =C26+C27 -> 772 | D25: =D26+D27 -> 798 | E25: =E26+E27 -> 707 | F25: =F26+F27 -> 562 | G25: =G23-G24 -> 562 | H25: =G25 -> 562 | I25: =I23-I24 -> 562 | J25: =J23-J24 -> 562 | K25: =K23-K24 -> 562 | L25: =L23-L24 -> 562
A26: Less: Accumulated amortization | C26: 348 | D26: 224 | E26: 247 | F26: 207 | G26: =F26+G29 -> 285 | H26: =G26+H29 -> 346 | I26: =H26+I29 -> 400 | J26: =I26+J29 -> 442 | K26: =J26+K29 -> 484 | L26: =K26+L29 -> 518
A27: Net block | C27: =C20 -> 424 | D27: =D20 -> 574 | E27: =E20 -> 460 | F27: =F20 -> 355 | G27: =G25-G26 -> 277 | H27: =H25-H26 -> 216 | I27: =I25-I26 -> 162 | J27: =J25-J26 -> 120 | K27: =K25-K26 -> 78 | L27: =L25-L26 -> 44
A29: Amortization | C29: =C13-C12 -> 235 | D29: =D13-D12 -> 190 | E29: =E13-E12 -> 135 | F29: =F13-F12 -> 110 | G29: =G13-G12 -> 78 | H29: 61 | I29: 54 | J29: 42 | K29: 42 | L29: 34

Sheet P&L
I1: (In millions except par value)
A2: Particulars | C2: Historical | H2: Forecast
B3: Unit | C3: 2020 | D3: =C3+1 -> 2021 | E3: =D3+1 -> 2022 | F3: =E3+1 -> 2023 | G3: =F3+1 -> 2024 | H3: =G3+1 -> 2025 | I3: =H3+1 -> 2026 | J3: =I3+1 -> 2027 | K3: =J3+1 -> 2028 | L3: =K3+1 -> 2029
A5: Total net operating revenue | B5: $ | C5: =Revenue!C45 -> 33014 | D5: =Revenue!D45 -> 38655 | E5: =Revenue!E45 -> 43004 | F5: =Revenue!F45 -> 45754 | G5: =Revenue!G45 -> 47061 | H5: =Revenue!H45 -> 52326.99 | I5: =Revenue!I45 -> 58242.849 | J5: =Revenue!J45 -> 64454.54 | ... L5: =Revenue!L45 -> 77377.155
A6: Add/Less: Extraordinary items | C6: -15 | D6: 3 | E6: 42 | F6: 30 | G6: -164 | H6: 0 | I6: 0 | J6: 0 | K6: 0
A7: Normalised revenue | C7: =C5+C6 -> 32999 | D7: =D5+D6 -> 38658 | E7: =E5+E6 -> 43046 | F7: =F5+F6 -> 45784 | G7: =G5+G6 -> 46897 | H7: =H5+H6 -> 52326.99 | I7: =I5+I6 -> 58242.849 | J7: =J5+J6 -> 64454.54 | ... L7: =L5+L6 -> 77377.155
A9: Cost of goods sold | C9: 13433 | D9: 15357 | E9: 18000 | F9: 18520 | G9: 18324
A10: Add/Less: Extraordinary items | C10: 65 | D10: 53 | E10: -183 | F10: -55 | G10: -70
A11: Normalised COGS | C11: =C9+C10 -> 13498 | D11: =D9+D10 -> 15410 | E11: =E9+E10 -> 17817 | F11: =F9+F10 -> 18465 | G11: =G9+G10 -> 18254 | H11: =H7-H12 -> 21078.519 | I11: =I7-I12 -> 23461.564 | J11: =J7-J12 -> 25963.776 | K11: =K7-K12 -> 28547.929 | L11: =L7-L12 -> 31169.304
A12: Normalised Gross Profit | C12: =C7-C11 -> 19501 | D12: =D7-D11 -> 23248 | E12: =E7-E11 -> 25229 | F12: =F7-F11 -> 27319 | G12: =G7-G11 -> 28643 | H12: =H7*H49 -> 31248.471 | I12: =I7*I49 -> 34781.285 | J12: =J7*J49 -> 38490.764 | K12: =K7*K49 -> 42321.716 | L12: =L7*L49 -> 46207.851
A14: Selling, general and administrative expenses | C14: 9731 | D14: 12144 | E14: 12880 | F14: 13972 | G14: 14582
A15: Add/Less: Extraordinary items | C15: 0 | D15: -5 | E15: 4 | F15: 11 | G15: -24
A16: Normalised Selling, general and administrative expenses | C16: =C14+C15 -> 9731 | D16: =D14+D15 -> 12139 | E16: =E14+E15 -> 12884 | F16: =F14+F15 -> 13983 | G16: =G14+G15 -> 14558 | H16: =H7*H50 -> 15949.715 | I16: =I7*I50 -> 17752.919 | J16: =J7*J50 -> 19646.296 | K16: =K7*K50 -> 21601.675 | L16: =L7*L50 -> 23585.22
A17: Other operating charges | C17: 853 | D17: 846 | E17: 1215 | F17: 1951 | G17: 4163
A18: Add/Less: Extraordinary items | C18: -853 | D18: -846 | E18: -1215 | F18: -1951 | G18: -4163
A19: Normalised Other operating charges | C19: =C17+C18 -> 0 | D19: =D17+D18 -> 0 | E19: =E17+E18 -> 0 | F19: =F17+F18 -> 0
A21: Normalised Operating Income (EBIT) | C21: =C12-C16-C19 -> 9770 | D21: =D12-D16-D19 -> 11109 | E21: =E12-E16-E19 -> 12345 | F21: =F12-F16-F19 -> 13336 | G21: =G12-G16-G19 -> 14085 | H21: =H12-H16-H19 -> 15298.756 | I21: =I12-I16-I19 -> 17028.366 | J21: =J12-J16-J19 -> 18844.468 | ... L21: =L12-L16-L19 -> 22622.632
A23: Interest income | C23: 370 | D23: 276 | E23: 449 | F23: 907 | G23: 988 | H23: =H60*AVERAGE('Balance Sheet'!G6:H6) -> 696.8251 | I23: =I60*AVERAGE('Balance Sheet'!H6:I6) -> 464.12855 | J23: =J60*AVERAGE('Balance Sheet'!I6:J6) -> 755.93948 | K23: =K60*AVERAGE('Balance Sheet'!J6:K6) -> 1048.61 | L23: =L60*AVERAGE('Balance Sheet'!K6:L6) -> 1271.773
A24: Interest expense | C24: 1437 | D24: 1597 | E24: 882 | F24: 1527 | G24: 1656
A25: Add/Less: Extraordinary items | C25: -484 | D25: -821 | E25: 24 | F25: 25 | G25: 25
A26: Normalised Interest expense | C26: =C24+C25 -> 953 | D26: =D24+D25 -> 776 | E26: =E24+E25 -> 906 | F26: =F24+F25 -> 1552 | G26: =G24+G25 -> 1681 | H26: =Debt!C26+Debt!C13 -> 1560.4486 | I26: =Debt!D26+Debt!D13 -> 1290.1201 | J26: =Debt!E26+Debt!E13 -> 1185.3863 | K26: =Debt!F26+Debt!F13 -> 1058.9704 | L26: =Debt!G26+Debt!G13 -> 887.43926
A27: Equity income (loss) — net | C27: 978 | D27: 1438 | E27: 1472 | F27: 1691 | G27: 1770 | H27: 1770 | I27: 1770 | J27: 1770 | K27: 1770 | L27: 1770
A28: Add/Less: Extraordinary items | C28: 216 | D28: 13 | E28: 34 | F28: 159 | G28: 92
A29: Normalised Equity income (loss) — net | C29: =C27+C28 -> 1194 | D29: =D27+D28 -> 1451 | E29: =E27+E28 -> 1506 | F29: =F27+F28 -> 1850 | G29: =G27+G28 -> 1862 | H29: =H53*H7 -> 1976.0156 | I29: =I53*I7 -> 2199.4152 | J29: =J53*J7 -> 2433.9862 | K29: =K53*K7 -> 2676.2388 | L29: =L53*L7 -> 2921.9808
A30: Other income (loss) — net | C30: 841 | D30: 2000 | E30: -262 | F30: 570 | G30: 1992
A31: Add/Less: Extraordinary items | C31: =316+14-944-110 -> -724 | D31: =117-1666-84 -> -1633 | E31: =96+443-294 -> 245 | F31: =39-855+108 -> -708 | G31: =34-1741-206 -> -1913
A32: Normalised Other income (loss) — net | C32: =C30+C31 -> 117 | D32: =D30+D31 -> 367 | E32: =E30+E31 -> -17 | F32: =F30+F31 -> -138 | G32: =G30+G31 -> 79 | H32: =AVERAGE(C32:G32) -> 81.6 | I32: =AVERAGE(D32:H32) -> 74.52 | J32: =AVERAGE(E32:I32) -> 16.024 | K32: =AVERAGE(F32:J32) -> 22.6288 | L32: =AVERAGE(G32:K32) -> 54.75456
A34: Normalised Income Before Income Taxes (PBT) | C34: =C21+C23-C26+C29+C32 -> 10498 | D34: =D21+D23-D26+D29+D32 -> 12427 | E34: =E21+E23-E26+E29+E32 -> 13377 | F34: =F21+F23-F26+F29+F32 -> 14403 | G34: =G21+G23-G26+G29+G32 -> 15333 | H34: =H21+H23-H26+H29+H32 -> 16492.748 | I34: =I21+I23-I26+I29+I32 -> 18476.31 | J34: =J21+J23-J26+J29+J32 -> 20865.031 | ... L34: =L21+L23-L26+L29+L32 -> 25983.701
A35: Income taxes | C35: 1981 | D35: 2621 | E35: 2115 | F35: 2249 | G35: 2437
A36: Add/Less: Extraordinary items | C36: =61+93+22+40+52-207 -> 61 | D36: =16+60+29-10-138+140-410 -> -313 | E36: =1+113+30+158+128 -> 430 | F36: =14+27+48+71+328 -> 488 | G36: =222+2+332+33-70-104 -> 415
A37: Normalised Income taxes | C37: =C35+C36 -> 2042 | D37: =D35+D36 -> 2308 | E37: =E35+E36 -> 2545 | F37: =F35+F36 -> 2737 | G37: =G35+G36 -> 2852 | H37: =H34*H52 -> 3122.1554 | I37: =I34*I52 -> 3497.653 | J37: =J34*J52 -> 3949.8493 | K37: =K34*K52 -> 4431.3492 | L37: =L34*L52 -> 4918.8377
A38: Consolidated Net Income | C38: =C34-C37 -> 8456 | D38: =D34-D37 -> 10119 | E38: =E34-E37 -> 10832 | F38: =F34-F37 -> 11666 | G38: =G34-G37 -> 12481 | H38: =H34-H37 -> 13370.593 | I38: =I34-I37 -> 14978.657 | J38: =J34-J37 -> 16915.182 | ... L38: =L34-L37 -> 21064.863
A39: Less: Net income (loss) attributable to noncontrolling interests | C39: 21 | D39: 33 | E39: 29 | F39: -11 | G39: 18 | H39: =H38*H55 -> 23.856264 | I39: =I38*I55 -> 26.725426 | J39: =J38*J55 -> 30.18064 | K39: =K38*K55 -> 33.859762 | L39: =L38*L55 -> 37.584642
A40: Net Income Attributable to Shareowners of The Coca-Cola Company | C40: =C38-C39 -> 8435 | D40: =D38-D39 -> 10086 | E40: =E38-E39 -> 10803 | F40: =F38-F39 -> 11677 | G40: =G38-G39 -> 12463 | H40: =H38-H39 -> 13346.737 | I40: =I38-I39 -> 14951.931 | J40: =J38-J39 -> 16885.001 | ... L40: =L38-L39 -> 21027.278
A42: Diluted EPS | C42: =C40/C43 -> 1.9511913 | D42: =D40/D43 -> 2.3239631 | E42: =E40/E43 -> 2.4834483 | F42: =F40/F43 -> 2.6911731 | G42: =G40/G43 -> 2.8849537 | H42: =H40/H43 -> 3.0895223 | I42: =I40/I43 -> 3.4610952 | J42: =J40/J43 -> 3.9085651 | ... L42: =L40/L43 -> 4.8674256
A43: Average Shares Outstanding — Diluted | C43: 4323 | D43: 4340 | E43: 4350 | F43: 4339 | G43: 4320 | H43: 4320 | I43: 4320 | J43: 4320 | K43: 4320 | L43: 4320
A45: Dividend per share | C45: 1.64 | D45: 1.68 | E45: 1.76 | F45: 1.84 | G45: 1.94 | H45: =H42*H46 -> 2.2419294 | I45: =I42*I46 -> 2.5115634 | J45: =J42*J46 -> 2.8362725 | K45: =K42*K46 -> 3.1820236 | L45: =L42*L46 -> 3.532075
A46: Dividend payout ratio | C46: =C45/C42 -> 0.84051215 | D46: =D45/D42 -> 0.72290303 | E46: =E45/E42 -> 0.70869203 | F46: =F45/F42 -> 0.68371671 | G46: =G45/G42 -> 0.67245447 | H46: =AVERAGE($C$46:$G$46) -> 0.72565568 | I46: =AVERAGE($C$46:$G$46) -> 0.72565568 | J46: =AVERAGE($C$46:$G$46) -> 0.72565568 | K46: =AVERAGE($C$46:$G$46) -> 0.72565568 | L46: =AVERAGE($C$46:$G$46) -> 0.72565568
A48: Workings
A49: GP margin % | C49: =C12/C7 -> 0.5909573 | D49: =D12/D7 -> 0.60137617 | E49: =E12/E7 -> 0.58609395 | F49: =F12/F7 -> 0.59669317 | G49: =G12/G7 -> 0.61076401 | H49: =AVERAGE(C49:G49) -> 0.59717692 | I49: =H49 -> 0.59717692 | J49: =I49 -> 0.59717692 | K49: =J49 -> 0.59717692 | L49: =K49 -> 0.59717692
...

Sheet Revenue
A2: Particulars | C2: Historical | H2: Forecast
B3: Unit | C3: =D3-1 -> 2020 | D3: =E3-1 -> 2021 | E3: =F3-1 -> 2022 | F3: =G3-1 -> 2023 | G3: =H3-1 -> 2024 | H3: =G3+1 -> 2025 | I3: =H3+1 -> 2026 | J3: =I3+1 -> 2027 | K3: =J3+1 -> 2028 | L3: =K3+1 -> 2029
A5: Europe, Middle East & Africa | C5: 6057 | D5: 7193 | E5: 7523 | F5: 8078 | G5: 8122 | H5: =G5*(1+H8) -> 9359.4477 | I5: =H5*(1+I8) -> 10662.921 | J5: =I5*(1+J8) -> 12008.355 | K5: =J5*(1+K8) -> 13366.372 | L5: =K5*(1+L8) -> 14703.009
A6: Growth rate% | D6: =D5/C5-1 -> 0.18755159 | E6: =E5/D5-1 -> 0.045877937 | F6: =F5/E5-1 -> 0.07377376 | G6: =G5/F5-1 -> 0.0054468928
A7: Add/Less: Inorganic growth | D7: -0.01 | E7: 0.124 | F7: 0.12 | G7: 0.16
A8: Organic | D8: =D6+D7 -> 0.17755159 | E8: =E6+E7 -> 0.16987794 | F8: =F6+F7 -> 0.19377376 | G8: =G6+G7 -> 0.16544689 | H8: =G8-($G$8-$L$8)/5 -> 0.15235751 | I8: =H8-($G$8-$L$8)/5 -> 0.13926814 | J8: =I8-($G$8-$L$8)/5 -> 0.12617876 | K8: =J8-($G$8-$L$8)/5 -> 0.11308938 | L8: 0.1
A10: Latin America | C10: 3499 | D10: 4143 | E10: 4910 | F10: 5830 | G10: 6459 | H10: =G10*(1+H13) -> 7920.7504 | I10: =H10*(1+I13) -> 9542.3983 | J10: =I10*(1+J13) -> 11290.147 | K10: =J10*(1+K13) -> 13114.387 | L10: =K10*(1+L13) -> 14950.401
A11: Growth rate% | D11: =D10/C10-1 -> 0.18405259 | E11: =E10/D10-1 -> 0.18513155 | F11: =F10/E10-1 -> 0.18737271 | G11: =G10/F10-1 -> 0.10789022
A12: Add/Less: Inorganic growth | D12: 0 | E12: 0.06 | F12: 0.03 | G12: 0.14
A13: Organic | D13: =D11+D12 -> 0.18405259 | E13: =E11+E12 -> 0.24513155 | F13: =F11+F12 -> 0.21737271 | G13: =G11+G12 -> 0.24789022 | H13: =G13-($G$13-$L$13)/5 -> 0.22631218 | I13: =H13-($G$13-$L$13)/5 -> 0.20473413 | J13: =I13-($G$13-$L$13)/5 -> 0.18315609 | K13: =J13-($G$13-$L$13)/5 -> 0.16157804 | L13: 0.14
A15: North America | C15: 11477 | D15: 13190 | E15: 15674 | F15: 16774 | G15: 18649 | H15: =G15*(1+H18) -> 20577.756 | I15: =H15*(1+I18) -> 22534.044 | J15: =I15*(1+J18) -> 24488.017 | K15: =J15*(1+K18) -> 26406.801 | L15: =K15*(1+L18) -> 28255.277
A16: Growth rate% | D16: =D15/C15-1 -> 0.14925503 | E16: =E15/D15-1 -> 0.18832449 | F16: =F15/E15-1 -> 0.070179916 | G16: =G15/F15-1 -> 0.11178014
A17: Add/Less: Inorganic growth | D17: 0 | E17: -0.06 | F17: 0 | G17: 0
A18: Organic | D18: =D16+D17 -> 0.14925503 | E18: =E16+E17 -> 0.12832449 | F18: =F16+F17 -> 0.070179916 | G18: =G16+G17 -> 0.11178014 | H18: =G18-($G$18-$L$18)/5 -> 0.10342411 | I18: =H18-($G$18-$L$18)/5 -> 0.095068082 | J18: =I18-($G$18-$L$18)/5 -> 0.086712054 | K18: =J18-($G$18-$L$18)/5 -> 0.078356027 | L18: 0.07
A20: Asia Pacific | C20: 4722 | D20: 5291 | E20: 5445 | F20: 5455 | G20: 5546 | H20: =G20*(1+H23) -> 5841.8544 | I20: =H20*(1+I23) -> 6192.4193 | J20: =I20*(1+J23) -> 6605.285 | K20: =J20*(1+K23) -> 7089.6928 | L20: =K20*(1+L23) -> 7656.8682
A21: Growth rate% | D21: =D20/C20-1 -> 0.12049979 | E21: =E20/D20-1 -> 0.029106029 | F21: =F20/E20-1 -> 0.0018365473 | G21: =G20/F20-1 -> 0.016681943
A22: Add/Less: Inorganic growth | D22: -0.03 | E22: 0.08 | F22: 0.04 | G22: 0.03
A23: Organic | D23: =D21+D22 -> 0.090499788 | E23: =E21+E22 -> 0.10910603 | F23: =F21+F22 -> 0.041836547 | G23: =G21+G22 -> 0.046681943 | H23: =G23-($G$23-$L$23)/5 -> 0.053345555 | I23: =H23-($G$23-$L$23)/5 -> 0.060009166 | J23: =I23-($G$23-$L$23)/5 -> 0.066672777 | K23: =J23-($G$23-$L$23)/5 -> 0.073336389 | L23: 0.08
A25: Global Ventures | C25: 1991 | D25: 2805 | E25: 2843 | F25: 3064 | G25: 3129 | H25: =G25*(1+H28) -> 3332.385 | I25: =H25*(1+I28) -> 3548.99 | J25: =I25*(1+J28) -> 3779.6744 | K25: =J25*(1+K28) -> 4025.3532 | L25: =K25*(1+L28) -> 4287.0012
A26: Growth rate% | D26: =D25/C25-1 -> 0.40883978 | E26: =E25/D25-1 -> 0.013547237 | F26: =F25/E25-1 -> 0.077734787 | G26: =G25/F25-1 -> 0.021214099
A27: Add/Less: Inorganic growth | D27: -0.08 | E27: 0.12 | F27: 0 | G27: -0.02
A28: Organic | D28: =D26+D27 -> 0.32883978 | E28: =E26+E27 -> 0.13354724 | F28: =F26+F27 -> 0.077734787 | G28: =G26+G27 -> 0.0012140992 | H28: 0.065 | I28: 0.065 | J28: 0.065 | K28: 0.065 | L28: 0.065
A30: Bottling Investments | C30: 6265 | D30: 7203 | E30: 7891 | F30: 7860 | G30: 6223 | H30: =G30*(1+H33) -> 6795.516 | I30: =H30*(1+I33) -> 7420.7035 | J30: =I30*(1+J33) -> 8103.4082 | K30: =J30*(1+K33) -> 8848.9217 | L30: =K30*(1+L33) -> 9663.0225
A31: Growth rate% | D31: =D30/C30-1 -> 0.14972067 | E31: =E30/D30-1 -> 0.095515757 | F31: =F30/E30-1 -> -0.0039285262 | G31: =G30/F30-1 -> -0.20826972
A32: Add/Less: Inorganic growth | D32: -0.02 | E32: 0.09 | F32: 0.14 | G32: 0.3
A33: Organic | D33: =D31+D32 -> 0.12972067 | E33: =E31+E32 -> 0.18551576 | F33: =F32+F31 -> 0.13607147 | G33: =G32+G31 -> 0.09173028 | H33: 0.092 | I33: 0.092 | J33: 0.092 | K33: 0.092 | L33: 0.092
A35: Corporate | C35: 46 | D35: 85 | E35: 94 | F35: 126 | G35: 97 | H35: =G35*(1+H38) -> 117.64112 | I35: =H35*(1+I38) -> 142.69868 | J35: =I35*(1+J38) -> 173.0935 | K35: =J35*(1+K38) -> 209.96241 | L35: =K35*(1+L38) -> 254.68441
A36: Growth rate% | D36: =D35/C35-1 -> 0.84782609 | E36: =E35/D35-1 -> 0.10588235 | F36: =F35/E35-1 -> 0.34042553 | G36: =G35/F35-1 -> -0.23015873
A37: Add/Less: Inorganic growth | C37: 0 | D37: 0 | E37: 0 | F37: 0
A38: Organic | C38: =C36+C37 -> 0 | D38: =D36+D37 -> 0.84782609 | E38: =E36+E37 -> 0.10588235 | F38: =F36+F37 -> 0.34042553 | G38: =G36+G37 -> -0.23015873 | H38: =AVERAGE(C38:G38) -> 0.21279505 | I38: 0.213 | J38: 0.213 | K38: 0.213 | L38: 0.213
A39: Total revenue before elemination | C39: =C35+C30+C25+C20+C15+C10+C5 -> 34057 | D39: =D35+D30+D25+D20+D15+D10+D5 -> 39910 | E39: =E35+E30+E25+E20+E15+E10+E5 -> 44380 | F39: =F35+F30+F25+F20+F15+F10+F5 -> 47187 | G39: =G35+G30+G25+G20+G15+G10+G5 -> 48225 | H39: =H35+H30+H25+H20+H15+H10+H5 -> 53945.351 | I39: =I35+I30+I25+I20+I15+I10+I5 -> 60044.174 | J39: =J35+J30+J25+J20+J15+J10+J5 -> 66447.98 | ... L39: =L35+L30+L25+L20+L15+L10+L5 -> 79770.263
A41: Eliminations | C41: -1043 | D41: -1255 | E41: -1376 | F41: -1433 | G41: -1164 | H41: =-H42*H39 -> -1618.3605 | I41: =-I42*I39 -> -1801.3252 | J41: =-J42*J39 -> -1993.4394 | K41: =-K42*K39 -> -2191.8447 | L41: =-L42*L39 -> -2393.1079
A42: Eliminations as % of revenue before elemination | C42: =-C41/C39 -> 0.030625128 | D42: =-D41/D39 -> 0.031445753 | E42: =-E41/E39 -> 0.031004957 | F42: =-F41/F39 -> 0.030368534 | G42: =-G41/G39 -> 0.024136858 | H42: 0.03 | I42: 0.03 | J42: 0.03 | K42: 0.03 | L42: 0.03
A45: Total revenue | C45: =C39+C41 -> 33014 | D45: =D39+D41 -> 38655 | E45: =E39+E41 -> 43004 | F45: =F39+F41 -> 45754 | G45: =G39+G41 -> 47061 | H45: =H39+H41 -> 52326.99 | I45: =I39+I41 -> 58242.849 | J45: =J39+J41 -> 64454.54 | ... L45: =L39+L41 -> 77377.155
D46: =D45/C45-1 -> 0.1708669 | E46: =E45/D45-1 -> 0.11250808 | F46: =F45/E45-1 -> 0.06394754 | G46: =G45/F45-1 -> 0.028565808 | H46: =H45/G45-1 -> 0.11189712 | I46: =I45/H45-1 -> 0.11305559 | J46: =J45/I45-1 -> 0.10665157 | K46: =K45/J45-1 -> 0.099529136 | L46: =L45/K45-1 -> 0.091823662
Y53: r
